Workbook

Sheet Roster
A1: Character | B1: Version | C1: Side | D1: Type | E1: Cost (pts) | F1: Max HP | G1: PWR | H1: SPD | I1: DEF | J1: Regen / round | K1: 1 HP = % of bar | L1: Regen as % of bar | M1: Strikes per Attack | N1: Max damage taken / round | O1: Max damage as % of bar | P1: Special | Q1: Special effect | R1: Cooldown (rounds) | S1: Passive
A2: Yoriichi Tsugikuni | B2: Legend | C2: Slayer | D2: Sun Breathing · Legend | E2: 18 | F2: 50 | G2: 15 | H2: 12 | I2: 7 | J2: 0 | K2: =1/F2 | L2: =J2/F2 | M2: 2 | N2: 18 | O2: =IF(N2="","",N2/F2) | P2: Sun Breathing: Thirteenth Form | Q2: Every enemy takes PWR, ignores DEF. Demons it hits lose their regeneration for good. | R2: 3 | S2: Transparent World: strikes twice every Attack and never takes more than 18 damage in a round.
A3: Yoriichi (Age 85) | B3: Legend | C3: Slayer | D3: Sun Breathing · Legend | E3: 15 | F3: 44 | G3: 13 | H3: 11 | I3: 5 | J3: 0 | K3: =1/F3 | L3: =J3/F3 | M3: 2 | N3: 12 | O3: =IF(N3="","",N3/F3) | P3: The Last Strike | Q3: Strike for PWR+10, ignores DEF. | R3: 3 | S3: Still the Strongest: strikes twice every Attack and never takes more than 12 damage in a round.
A4: Muzan Kibutsuji (Final Form) | B4: Final Form | C4: Demon | D4: Demon King · Final Form | E4: 18 | F4: 52 | G4: 17 | H4: 11 | I4: 8 | J4: 5 | K4: =1/F4 | L4: =J4/F4 | M4: 1 | O4: =IF(N4="","",N4/F4) | P4: Thorned Flesh Whips | Q4: Every enemy takes PWR−6, ignores DEF, and he heals 3 for each enemy hit. | R4: 3 | S4: Seven Hearts: the first time he falls, he gets back up with 20% health.
A5: Muzan Kibutsuji | B5: Base | C5: Demon | D5: Demon King | E5: 16 | F5: 54 | G5: 17 | H5: 11 | I5: 8 | J5: 4 | K5: =1/F5 | L5: =J5/F5 | M5: 1 | O5: =IF(N5="","",N5/F5) | P5: Blood Whips | Q5: Every enemy takes PWR−7, ignores DEF, and Muzan heals 2 for each enemy hit. | R5: 3
A6: Kokushibo | B6: Base | C6: Demon | D6: Upper Moon 1 | E6: 15 | F6: 50 | G6: 17 | H6: 11 | I6: 8 | J6: 3 | K6: =1/F6 | L6: =J6/F6 | M6: 1 | O6: =IF(N6="","",N6/F6) | P6: Moon Breathing | Q6: Every enemy takes PWR−4, ignores DEF. | R6: 3
A7: Akaza | B7: Base | C7: Demon | D7: Upper Moon 3 | E7: 9 | F7: 40 | G7: 13 | H7: 10 | I7: 5 | J7: 2 | K7: =1/F7 | L7: =J7/F7 | M7: 1 | O7: =IF(N7="","",N7/F7) | P7: Destructive Death | Q7: Strike for PWR+6. | R7: 3
A8: Hantengu | B8: Base | C8: Demon | D8: Upper Moon 4 | E8: 9 | F8: 20 | G8: 8 | H8: 9 | I8: 4 | J8: 1 | K8: =1/F8 | L8: =J8/F8 | M8: 1 | O8: =IF(N8="","",N8/F8) | P8: Cowering Hide | Q8: Moves first. Hides: attacks miss him this round, and he heals 6. | R8: 3 | S8: Splitting Emotions: when Hantengu falls he splits into Sekido and Karaku. When Sekido falls, Aizetsu takes his place; when Karaku falls, Urogi does. Beat all five to win.
A9: Doma | B9: Base | C9: Demon | D9: Upper Moon 2 | E9: 8 | F9: 37 | G9: 11 | H9: 9 | I9: 5 | J9: 2 | K9: =1/F9 | L9: =J9/F9 | M9: 1 | O9: =IF(N9="","",N9/F9) | P9: Frozen Lotus | Q9: Every enemy takes 8, ignores DEF. | R9: 3
A10: Gyokko | B10: Base | C10: Demon | D10: Upper Moon 5 | E10: 6 | F10: 32 | G10: 10 | H10: 8 | I10: 4 | J10: 2 | K10: =1/F10 | L10: =J10/F10 | M10: 1 | O10: =IF(N10="","",N10/F10) | P10: Water Prison Pot | Q10: Traps one enemy: it takes PWR−2 (ignores DEF) and can't act next round. | R10: 3
A11: Gyutaro & Daki | B11: Base | C11: Demon | D11: Upper Moon 6 | E11: 6 | F11: 30 | G11: 9 | H11: 8 | I11: 4 | J11: 2 | K11: =1/F11 | L11: =J11/F11 | M11: 1 | O11: =IF(N11="","",N11/F11) | P11: Flying Blood Sickles | Q11: Every enemy takes 4 and is poisoned 2/round for 2 rounds. | R11: 3
A12: Kaigaku | B12: Base | C12: Demon | D12: Upper Moon 6 · fallen Thunder | E12: 5 | F12: 26 | G12: 9 | H12: 10 | I12: 3 | J12: 1 | K12: =1/F12 | L12: =J12/F12 | M12: 1 | O12: =IF(N12="","",N12/F12) | P12: Black Thunder | Q12: Strike for PWR+3, and a second random enemy takes 4. | R12: 3 | S12: Rival: an enemy Zenitsu gets +2 PWR against him.
A13: Enmu | B13: Base | C13: Demon | D13: Lower Moon 1 | E13: 4 | F13: 28 | G13: 8 | H13: 8 | I13: 3 | J13: 1 | K13: =1/F13 | L13: =J13/F13 | M13: 1 | O13: =IF(N13="","",N13/F13) | P13: Forced Sleep | Q13: Every enemy has to wait 2 more rounds for their special. | R13: 3
A14: Rui | B14: Base | C14: Demon | D14: Lower Moon 5 | E14: 4 | F14: 24 | G14: 7 | H14: 7 | I14: 4 | J14: 1 | K14: =1/F14 | L14: =J14/F14 | M14: 1 | O14: =IF(N14="","",N14/F14) | P14: Cutting Thread Cage | Q14: Strike for PWR and stun the target next round. | R14: 3
A15: Kyogai | B15: Base | C15: Demon | D15: Former Lower Moon | E15: 3 | F15: 22 | G15: 6 | H15: 6 | I15: 3 | J15: 1 | K15: =1/F15 | L15: =J15/F15 | M15: 1 | O15: =IF(N15="","",N15/F15) | P15: Drum Room Spin | Q15: Flip the room. The target is stunned next round. | R15: 4
A16: Swamp Demon | B16: Base | C16: Demon | D16: Lesser demon | E16: 3 | F16: 16 | G16: 5 | H16: 8 | I16: 2 | J16: 1 | K16: =1/F16 | L16: =J16/F16 | M16: 1 | O16: =IF(N16="","",N16/F16) | P16: Swamp Dive | Q16: Moves early. Sinks out of reach this round and strikes for PWR+1. | R16: 2
A17: Hand Demon | B17: Base | C17: Demon | D17: Final Selection | E17: 2 | F17: 16 | G17: 5 | H17: 4 | I17: 3 | J17: 1 | K17: =1/F17 | L17: =J17/F17 | M17: 1 | O17: =IF(N17="","",N17/F17) | P17: Grasping Arms | Q17: Strike for PWR+3. | R17: 2
A18: Sekido (Anger) | B18: Split form | C18: Demon | D18: Hantengu split · Anger | E18: 0 | F18: 14 | G18: 7 | H18: 8 | I18: 3 | J18: 1 | K18: =1/F18 | L18: =J18/F18 | M18: 1 | O18: =IF(N18="","",N18/F18) | P18: Lightning Staff | Q18: Every enemy takes 4, ignores DEF. | R18: 3 | S18: Appears when Hantengu falls. Not drafted.
A19: Karaku (Joy) | B19: Split form | C19: Demon | D19: Hantengu split · Joy | E19: 0 | F19: 14 | G19: 7 | H19: 10 | I19: 3 | J19: 1 | K19: =1/F19 | L19: =J19/F19 | M19: 1 | O19: =IF(N19="","",N19/F19) | P19: Gale Fan | Q19: Strike for PWR+3. | R19: 2 | S19: Appears when Hantengu falls. Not drafted.
A20: Aizetsu (Sorrow) | B20: Split form | C20: Demon | D20: Hantengu split · Sorrow | E20: 0 | F20: 10 | G20: 7 | H20: 9 | I20: 3 | J20: 1 | K20: =1/F20 | L20: =J20/F20 | M20: 1 | O20: =IF(N20="","",N20/F20) | P20: Cross Spear | Q20: Strike for PWR+4. | R20: 3 | S20: Appears when Sekido falls. Not drafted.
A21: Urogi (Pleasure) | B21: Split form | C21: Demon | D21: Hantengu split · Pleasure | E21: 0 | F21: 10 | G21: 6 | H21: 11 | I21: 2 | J21: 1 | K21: =1/F21 | L21: =J21/F21 | M21: 1 | O21: =IF(N21="","",N21/F21) | P21: Sky Dive | Q21: Moves early. Swoops down for PWR+2. | R21: 2 | S21: Appears when Karaku falls. Not drafted.
A22: Gyomei Himejima (Mark) | B22: Mark | C22: Slayer | D22: Stone Hashira | E22: 12 | F22: 50 | G22: 17 | H22: 9 | I22: 8 | J22: 0 | K22: =1/F22 | L22: =J22/F22 | M22: 1 | O22: =IF(N22="","",N22/F22) | P22: Volcanic Rock | Q22: Every enemy takes PWR−3. | R22: 2 | S22: Mark awakened: boosted stats and the special recharges 1 round faster.
A23: Giyu Tomioka (Mark) | B23: Mark | C23: Slayer | D23: Water Hashira | E23: 10 | F23: 40 | G23: 14 | H23: 10 | I23: 6 | J23: 0 | K23: =1/F23 | L23: =J23/F23 | M23: 1 | O23: =IF(N23="","",N23/F23) | P23: Dead Calm | Q23: Moves first. Your whole team takes no damage this round. | R23: 3 | S23: Mark awakened: boosted stats and the special recharges 1 round faster.
A24: Muichiro Tokito (Mark) | B24: Mark | C24: Slayer | D24: Mist Hashira | E24: 10 | F24: 34 | G24: 14 | H24: 13 | I24: 5 | J24: 0 | K24: =1/F24 | L24: =J24/F24 | M24: 1 | O24: =IF(N24="","",N24/F24) | P24: Obscuring Clouds | Q24: Moves early. Vanishes into mist (attacks miss him this round) and strikes for PWR+2. | R24: 2 | S24: Mark awakened: boosted stats and the special recharges 1 round faster.
A25: Sanemi Shinazugawa (Mark) | B25: Mark | C25: Slayer | D25: Wind Hashira | E25: 10 | F25: 42 | G25: 15 | H25: 11 | I25: 6 | J25: 0 | K25: =1/F25 | L25: =J25/F25 | M25: 1 | O25: =IF(N25="","",N25/F25) | P25: Black Wind Mountain Mist | Q25: Strike your target and one other enemy for PWR. | R25: 2 | S25: Mark awakened: boosted stats and the special recharges 1 round faster.
A26: Giyu Tomioka | B26: Base | C26: Slayer | D26: Water Hashira | E26: 8 | F26: 32 | G26: 10 | H26: 8 | I26: 5 | J26: 0 | K26: =1/F26 | L26: =J26/F26 | M26: 1 | O26: =IF(N26="","",N26/F26) | P26: Dead Calm | Q26: Moves first. Your whole team takes no damage this round. | R26: 4
A27: Gyomei Himejima | B27: Base | C27: Slayer | D27: Stone Hashira | E27: 8 | F27: 42 | G27: 13 | H27: 7 | I27: 7 | J27: 0 | K27: =1/F27 | L27: =J27/F27 | M27: 1 | O27: =IF(N27="","",N27/F27) | P27: Volcanic Rock | Q27: Every enemy takes PWR−3. | R27: 3
A28: Mitsuri Kanroji (Mark) | B28: Mark | C28: Slayer | D28: Love Hashira | E28: 8 | F28: 36 | G28: 13 | H28: 11 | I28: 5 | J28: 0 | K28: =1/F28 | L28: =J28/F28 | M28: 1 | O28: =IF(N28="","",N28/F28) | P28: Catlove Shower | Q28: Every enemy takes PWR−3. | R28: 2 | S28: Mark awakened: boosted stats and the special recharges 1 round faster.
A29: Obanai Iguro (Mark) | B29: Mark | C29: Slayer | D29: Serpent Hashira | E29: 8 | F29: 34 | G29: 13 | H29: 12 | I29: 5 | J29: 0 | K29: =1/F29 | L29: =J29/F29 | M29: 1 | O29: =IF(N29="","",N29/F29) | P29: Twin-Headed Reptile | Q29: Strike for PWR+4. Slips past guards (Defend does nothing). | R29: 2 | S29: Mark awakened: boosted stats and the special recharges 1 round faster.
A30: Tanjiro Kamado (Mark) | B30: Mark | C30: Slayer | D30: Sun & Water | E30: 8 | F30: 36 | G30: 12 | H30: 9 | I30: 5 | J30: 0 | K30: =1/F30 | L30: =J30/F30 | M30: 1 | O30: =IF(N30="","",N30/F30) | P30: Hinokami Kagura | Q30: Strike for PWR+5, ignores DEF. | R30: 2 | S30: Mark awakened: boosted stats and the special recharges 1 round faster.
A31: Kyojuro Rengoku | B31: Base | C31: Slayer | D31: Flame Hashira | E31: 7 | F31: 34 | G31: 11 | H31: 7 | I31: 5 | J31: 0 | K31: =1/F31 | L31: =J31/F31 | M31: 1 | O31: =IF(N31="","",N31/F31) | P31: Ninth Form: Rengoku | Q31: Strike for PWR+8. | R31: 3
A32: Muichiro Tokito | B32: Base | C32: Slayer | D32: Mist Hashira | E32: 6 | F32: 26 | G32: 10 | H32: 11 | I32: 4 | J32: 0 | K32: =1/F32 | L32: =J32/F32 | M32: 1 | O32: =IF(N32="","",N32/F32) | P32: Obscuring Clouds | Q32: Moves early. Vanishes into mist (attacks miss him this round) and strikes for PWR+2. | R32: 3
A33: Sanemi Shinazugawa | B33: Base | C33: Slayer | D33: Wind Hashira | E33: 6 | F33: 34 | G33: 11 | H33: 9 | I33: 5 | J33: 0 | K33: =1/F33 | L33: =J33/F33 | M33: 1 | O33: =IF(N33="","",N33/F33) | P33: Black Wind Mountain Mist | Q33: Strike your target and one other enemy for PWR. | R33: 3
A34: Tengen Uzui | B34: Base | C34: Slayer | D34: Sound Hashira | E34: 6 | F34: 34 | G34: 10 | H34: 8 | I34: 5 | J34: 0 | K34: =1/F34 | L34: =J34/F34 | M34: 1 | O34: =IF(N34="","",N34/F34) | P34: Constant Resounding Slashes | Q34: Every enemy takes PWR−2. | R34: 3
A35: Mitsuri Kanroji | B35: Base | C35: Slayer | D35: Love Hashira | E35: 5 | F35: 28 | G35: 9 | H35: 9 | I35: 4 | J35: 0 | K35: =1/F35 | L35: =J35/F35 | M35: 1 | O35: =IF(N35="","",N35/F35) | P35: Catlove Shower | Q35: Every enemy takes PWR−3. | R35: 3
A36: Obanai Iguro | B36: Base | C36: Slayer | D36: Serpent Hashira | E36: 5 | F36: 26 | G36: 9 | H36: 10 | I36: 4 | J36: 0 | K36: =1/F36 | L36: =J36/F36 | M36: 1 | O36: =IF(N36="","",N36/F36) | P36: Twin-Headed Reptile | Q36: Strike for PWR+4. Slips past guards (Defend does nothing). | R36: 3
A37: Shinobu Kocho | B37: Base | C37: Slayer | D37: Insect Hashira | E37: 5 | F37: 24 | G37: 6 | H37: 10 | I37: 3 | J37: 0 | K37: =1/F37 | L37: =J37/F37 | M37: 1 | O37: =IF(N37="","",N37/F37) | P37: Wisteria Poison | Q37: Poison a target for 3 rounds: 6/round to demons, 3/round to humans. | R37: 3 | S37: Wisteria Body: if a demon lands the blow that knocks her out, it devours her and loses 5 HP every round for the rest of the match.
A38: Tanjiro Kamado | B38: Base | C38: Slayer | D38: Sun & Water | E38: 5 | F38: 28 | G38: 8 | H38: 7 | I38: 4 | J38: 0 | K38: =1/F38 | L38: =J38/F38 | M38: 1 | O38: =IF(N38="","",N38/F38) | P38: Hinokami Kagura | Q38: Strike for PWR+5, ignores DEF. | R38: 3
A39: Inosuke Hashibira | B39: Base | C39: Slayer | D39: Beast | E39: 4 | F39: 28 | G39: 8 | H39: 8 | I39: 3 | J39: 0 | K39: =1/F39 | L39: =J39/F39 | M39: 1 | O39: =IF(N39="","",N39/F39) | P39: Fang Frenzy | Q39: Two wild strikes of PWR−1 at random enemies. | R39: 2
A40: Kanao Tsuyuri | B40: Base | C40: Slayer | D40: Flower | E40: 4 | F40: 24 | G40: 7 | H40: 10 | I40: 3 | J40: 0 | K40: =1/F40 | L40: =J40/F40 | M40: 1 | O40: =IF(N40="","",N40/F40) | P40: Equinoctial Vermilion Eye | Q40: Moves early. Strike for PWR+4. | R40: 3
...

Sheet HP % Calculator
A1: HP → Percent converter
A2: Pick a character and type the HP they have left (blue cells). The bar shows what players will see.
A4: Character | B4: HP left | C4: Max HP | D4: Health % | E4: Shown to player
A5: Tanjiro Kamado | B5: 14 | C5: =IF(A5="","",INDEX(Roster!$F$2:$F$50,MATCH(A5,Roster!$A$2:$A$50,0))) | D5: =IF(OR(A5="",B5=""),"",MAX(0,MIN(1,B5/C5))) | E5: =IF(D5="","",ROUND(D5*100,0)&"% Health")
A6: Yoriichi Tsugikuni | B6: 26 | C6: =IF(A6="","",INDEX(Roster!$F$2:$F$50,MATCH(A6,Roster!$A$2:$A$50,0))) | D6: =IF(OR(A6="",B6=""),"",MAX(0,MIN(1,B6/C6))) | E6: =IF(D6="","",ROUND(D6*100,0)&"% Health")
A7: Muzan Kibutsuji | B7: 12 | C7: =IF(A7="","",INDEX(Roster!$F$2:$F$50,MATCH(A7,Roster!$A$2:$A$50,0))) | D7: =IF(OR(A7="",B7=""),"",MAX(0,MIN(1,B7/C7))) | E7: =IF(D7="","",ROUND(D7*100,0)&"% Health")
A8: Murata | B8: 5 | C8: =IF(A8="","",INDEX(Roster!$F$2:$F$50,MATCH(A8,Roster!$A$2:$A$50,0))) | D8: =IF(OR(A8="",B8=""),"",MAX(0,MIN(1,B8/C8))) | E8: =IF(D8="","",ROUND(D8*100,0)&"% Health")
A9: Gyomei Himejima (Mark) | B9: 30 | C9: =IF(A9="","",INDEX(Roster!$F$2:$F$50,MATCH(A9,Roster!$A$2:$A$50,0))) | D9: =IF(OR(A9="",B9=""),"",MAX(0,MIN(1,B9/C9))) | E9: =IF(D9="","",ROUND(D9*100,0)&"% Health")
C10: =IF(A10="","",INDEX(Roster!$F$2:$F$50,MATCH(A10,Roster!$A$2:$A$50,0))) | D10: =IF(OR(A10="",B10=""),"",MAX(0,MIN(1,B10/C10))) | E10: =IF(D10="","",ROUND(D10*100,0)&"% Health")
C11: =IF(A11="","",INDEX(Roster!$F$2:$F$50,MATCH(A11,Roster!$A$2:$A$50,0))) | D11: =IF(OR(A11="",B11=""),"",MAX(0,MIN(1,B11/C11))) | E11: =IF(D11="","",ROUND(D11*100,0)&"% Health")
C12: =IF(A12="","",INDEX(Roster!$F$2:$F$50,MATCH(A12,Roster!$A$2:$A$50,0))) | D12: =IF(OR(A12="",B12=""),"",MAX(0,MIN(1,B12/C12))) | E12: =IF(D12="","",ROUND(D12*100,0)&"% Health")
C13: =IF(A13="","",INDEX(Roster!$F$2:$F$50,MATCH(A13,Roster!$A$2:$A$50,0))) | D13: =IF(OR(A13="",B13=""),"",MAX(0,MIN(1,B13/C13))) | E13: =IF(D13="","",ROUND(D13*100,0)&"% Health")
C14: =IF(A14="","",INDEX(Roster!$F$2:$F$50,MATCH(A14,Roster!$A$2:$A$50,0))) | D14: =IF(OR(A14="",B14=""),"",MAX(0,MIN(1,B14/C14))) | E14: =IF(D14="","",ROUND(D14*100,0)&"% Health")
A16: Rule for the UI: Health % = HP left ÷ Max HP, rounded to the nearest whole percent. Show red at 25% or less.
